answers,creation_date,len,postid,question,ratio,raw,tags,title,uniq,words,probability
command try work output fine! file save directori script ran script,2018-10-09 09:10:18.42 UTC,195,52717319,possibl point solut well code error traceback recent call last file /library/frameworks/python.framework/versions/3.6/lib/python3.6/urllib/request.pi line 1318 do_open encode_chunked=req.has_head transfer-encod file /library/frameworks/python.framework/versions/3.6/lib/python3.6/http/client.pi line 1239 request self._send_requestmethod url bodi header encode_chunk file /library/frameworks/python.framework/versions/3.6/lib/python3.6/http/client.pi line 1285 _send_request self.endheadersbodi encode_chunked=encode_chunk file /library/frameworks/python.framework/versions/3.6/lib/python3.6/http/client.pi line 1234 endhead self._send_outputmessage_bodi encode_chunked=encode_chunk file /library/frameworks/python.framework/versions/3.6/lib/python3.6/http/client.pi line 1026 _send_output self.sendmsg file /library/frameworks/python.framework/versions/3.6/lib/python3.6/http/client.pi line 964 send self.connect file /library/frameworks/python.framework/versions/3.6/lib/python3.6/http/client.pi line 1400 connect server_hostname=server_hostnam file /library/frameworks/python.framework/versions/3.6/lib/python3.6/ssl.pi line 407 wrap_socket _context=self _session=sess file /library/frameworks/python.framework/versions/3.6/lib/python3.6/ssl.pi line 814 init self.do_handshak file /library/frameworks/python.framework/versions/3.6/lib/python3.6/ssl.pi line 1068 do_handshak self._sslobj.do_handshak file /library/frameworks/python.framework/versions/3.6/lib/python3.6/ssl.pi line 689 do_handshak self._sslobj.do_handshak ssl.sslerror [ssl certificate_verify_failed] certif verifi fail _ssl.c:777 handl except anoth except occur traceback recent call last file /users/macintosh/pycharmprojects/claculatorer/bucky.pi line 9 download_web_imag https://upload.wikimedia.org/wikipedia/commons/b/b4/jpeg_example_jpg_rip_100.jpg file /users/macintosh/pycharmprojects/claculatorer/bucky.pi line 7 download_web_imag urllib.request.urlretrieveurl fullnam file /library/frameworks/python.framework/versions/3.6/lib/python3.6/urllib/request.pi line 248 urlretriev contextlib.closingurlopenurl data fp file /library/frameworks/python.framework/versions/3.6/lib/python3.6/urllib/request.pi line 223 urlopen return opener.openurl data timeout file /library/frameworks/python.framework/versions/3.6/lib/python3.6/urllib/request.pi line 526 open respons = self._openreq data file /library/frameworks/python.framework/versions/3.6/lib/python3.6/urllib/request.pi line 544 _open _open req file /library/frameworks/python.framework/versions/3.6/lib/python3.6/urllib/request.pi line 504 _call_chain result = func*arg file /library/frameworks/python.framework/versions/3.6/lib/python3.6/urllib/request.pi line 1361 https_open context=self._context check_hostname=self._check_hostnam file /library/frameworks/python.framework/versions/3.6/lib/python3.6/urllib/request.pi line 1320 do_open rais urlerrorerr urllib.error.urlerror process finish exit code 1,0.12307692307692308,24,python python-3.x ssl ssl-certificate web-crawler,fail download imag urllib.request.urlretriev python,4,ssl|certificate|encode|scripting,0.604706346988678
turn error .twitter_keys.yaml file endpoint incorrect endpoint case 30day chang full_arch etc,2019-02-04 18:51:51.04 UTC,127,54522534,seem key error valid credenti .twitter_keys.yaml file error show line twitter_search.pi file get follow error c:\users\hp\dev\twitter\twitter_search\src>python twitter_search.pi grab bearer token oauth {queri superbowl maxresult 100} traceback recent call last file twitter_search.pi line 17 result_stream_args=premium_search_arg file c:\program file x86\python36-32\lib\site-packages\searchtweets\result_stream.pi line 308 collect_result return listrs.stream file c:\program file x86\python36-32\lib\site-packages\searchtweets\result_stream.pi line 208 stream self.execute_request file c:\program file x86\python36-32\lib\site-packages\searchtweets\result_stream.pi line 263 execute_request resp = json.loadsresp.content.decoderesp.encod file c:\program file x86\python36-32\lib\json__init__.pi line 354 load return _default_decoder.decod file c:\program file x86\python36-32\lib\json\decoder.pi line 339 decod obj end = self.raw_decod idx=_w 0.end file c:\program file x86\python36-32\lib\json\decoder.pi line 357 raw_decod rais jsondecodeerrorexpect valu err.valu none json.decoder.jsondecodeerror expect valu line 1 column 1 char 0,0.11811023622047244,15,api python twitter,twitter api searchtweet modul error line - result_stream_args=premium_search_arg,5,validate|credential|oauth|decode|encode,0.508155107498169
none,2020-03-17 08:54:37,167,60719024,import gspreadfrom oauth2client.service_account import serviceaccountcredenti scope = [ https://spreadsheets.google.com/f ]cred = serviceaccountcredentials.from_json_keyfile_nam 96e165f08e7e.json scopecli = gspread.authorizecr sheet = client.openap日报.sheet1 list_of_hash = sheet.get_all_recordsprintlist_of_hash /users/daiou/pycharmprojects/gsworkeditor/venv/bin/python /users/daiou/pycharmprojects/gsworkeditor/gswoker.pytraceback recent call last file /users/daiou/pycharmprojects/gsworkeditor/gswoker.pi line 7 client = gspread.authorizecr file /users/daiou/pycharmprojects/gsworkeditor/venv/lib/python3.6/site-packages/gspread/ init .py line 38 author client.login file /users/daiou/pycharmprojects/gsworkeditor/venv/lib/python3.6/site-packages/gspread/client.pi line 51 login self.auth.refreshhttp file /users/daiou/pycharmprojects/gsworkeditor/venv/lib/python3.6/site-packages/oauth2client/client.pi line 545 refresh self._refreshhttp file /users/daiou/pycharmprojects/gsworkeditor/venv/lib/python3.6/site-packages/oauth2client/client.pi line 749 _refresh self._do_refresh_requesthttp file /users/daiou/pycharmprojects/gsworkeditor/venv/lib/python3.6/site-packages/oauth2client/client.pi line 780 _do_refresh_request body=bodi headers=head file /users/daiou/pycharmprojects/gsworkeditor/venv/lib/python3.6/site-packages/oauth2client/transport.pi line 282 request connection_type=connection_typ file /users/daiou/pycharmprojects/gsworkeditor/venv/lib/python3.6/site-packages/httplib2/ init .py line 1991 request cachekey file /users/daiou/pycharmprojects/gsworkeditor/venv/lib/python3.6/site-packages/httplib2/ init .py line 1651 _request conn request_uri method bodi header file /users/daiou/pycharmprojects/gsworkeditor/venv/lib/python3.6/site-packages/httplib2/ init .py line 1557 _conn_request conn.connect file /users/daiou/pycharmprojects/gsworkeditor/venv/lib/python3.6/site-packages/httplib2/ init .py line 1391 connect rai socket_err file /users/daiou/pycharmprojects/gsworkeditor/venv/lib/python3.6/site-packages/httplib2/ init .py line 1326 connect self.sock = self._context.wrap_socketsock server_hostname=self.host file /library/frameworks/python.framework/versions/3.6/lib/python3.6/ssl.pi line 407 wrap_socket _context=self _session=sess file /library/frameworks/python.framework/versions/3.6/lib/python3.6/ssl.pi line 817 init self.do_handshak file /library/frameworks/python.framework/versions/3.6/lib/python3.6/ssl.pi line 1077 do_handshak self._sslobj.do_handshak file /library/frameworks/python.framework/versions/3.6/lib/python3.6/ssl.pi line 689 do_handshak self._sslobj.do_handshakeconnectionreseterror [errno 54] connect reset peer process finish exit code 1,0.12574850299401197,21,python python-3.x gspread,gspread connectionreseterror [errno 54] connect reset peer,7,oauth|credential|authorise|hash|login|transport|ssl,0.49507150053977966
add line code,2018-08-23 07:24:05.13 UTC,292,51980383,"use follow python code connect tableau server import tableauservercli tsc tableau_auth = tsc.tableauauth usernam password server = tsc.server https://server_name.com/ server.auth.sign_intableau_auth get follow error traceback recent call last file c:\program files\anaconda3\lib\site-packages\urllib3\contrib\pyopenssl.pi line 444 wrap_socket cnx.do_handshak file c:\program files\anaconda3\lib\site-packages\openssl\ssl.pi line 1443 do_handshak self._raise_ssl_errorself._ssl result file c:\program files\anaconda3\lib\site-packages\openssl\ssl.pi line 1191 _raise_ssl_error _raise_current_error file c:\program files\anaconda3\lib\site-packages\openssl_util.pi line 48 exception_from_error_queu rais exception_typeerrorsopenssl.ssl.error [ ssl routin ssl3_get_server_certif certif verifi fail ] handl except anoth except occur traceback recent call last file c:\program files\anaconda3\lib\site-packages\urllib3\connectionpool.pi line 600 urlopen chunked=chunk file c:\program files\anaconda3\lib\site-packages\urllib3\connectionpool.pi line 343 _make_request self._validate_connconn file c:\program files\anaconda3\lib\site-packages\urllib3\connectionpool.pi line 849 _validate_conn conn.connect file c:\program files\anaconda3\lib\site-packages\urllib3\connection.pi line 356 connect ssl_context=context file c:\program files\anaconda3\lib\site-packages\urllib3\util\ssl_.pi line 359 ssl_wrap_socket return context.wrap_socketsock server_hostname=server_hostnam file c:\program files\anaconda3\lib\site-packages\urllib3\contrib\pyopenssl.pi line 450 wrap_socket rais ssl.sslerror bad handshak %r % essl.sslerror bad handshak error[ ssl routin ssl3_get_server_certif certif verifi fail ], handl except anoth except occur traceback recent call last file c:\program files\anaconda3\lib\site-packages\requests\adapters.pi line 445 send timeout=timeout file c:\program files\anaconda3\lib\site-packages\urllib3\connectionpool.pi line 638 urlopen _stacktrace=sys.exc_info[2] file c:\program files\anaconda3\lib\site-packages\urllib3\util\retry.pi line 398 increment rais maxretryerror_pool url error responseerrorcauseurllib3.exceptions.maxretryerror httpsconnectionpoolhost= server_name.com port=443 max retri exceed url //api/2.3/auth/signin caus sslerrorsslerrorbad handshak error[ ssl routin ssl3_get_server_certif certif verifi fail ],, handl except anoth except occur traceback recent call last file line 1 file c:\program files\anaconda3\lib\site-packages\tableauserverclient\server\endpoint\endpoint.pi line 114 wrapper return funcself *arg **kwarg file c:\program files\anaconda3\lib\site-packages\tableauserverclient\server\endpoint\auth_endpoint.pi line 30 sign_in **self.parent_srv.http_opt file c:\program files\anaconda3\lib\site-packages\requests\sessions.pi line 559 post return self.request post url data=data json=json **kwarg file c:\program files\anaconda3\lib\site-packages\requests\sessions.pi line 512 request resp = self.sendprep **send_kwarg file c:\program files\anaconda3\lib\site-packages\requests\sessions.pi line 622 send r = adapter.sendrequest **kwarg file c:\program files\anaconda3\lib\site-packages\requests\adapters.pi line 511 send rais sslerror request=requestrequests.exceptions.sslerror httpsconnectionpoolhost= server_name.com port=443 max retri exceed url //api/2.3/auth/signin caus sslerrorsslerrorbad handshak error[ ssl routin ssl3_get_server_certif certif verifi fail ],",0.1678082191780822,49,python tableau tableau-server,unabl connect tableau server 10.5 use tableauservercli python librari,7,username|password|signing|openssl|ssl|certificate|validate,0.4949532151222229
,2018-01-09 14:48:51.253 UTC,215,48170735,run script sure run use connect network devic use modul run pycharm tool windows10x64 machin got error unknown except dll load fail specifi modul found traceback recent call last file c:\users\selvam\venv\lib\site-packages\paramiko\transport.pi line 1888 run self.kex_engine.parse_nextptyp file c:\users\selvam\venv\lib\site-packages\paramiko\kex_group1.pi line 75 parse_next return self._parse_kexdh_replym file c:\users\selvam\venv\lib\site-packages\paramiko\kex_group1.pi line 114 _parse_kexdh_repli self.transport._verify_keyhost_key sig file c:\users\selvam\venv\lib\site-packages\paramiko\transport.pi line 1747 _verify_key key = self._key_infoself.host_key_typ file c:\users\selvam\venv\lib\site-packages\paramiko\rsakey.pi line 62 init .public_keydefault_backend file c:\users\selvam\appdata\local\continuum\anaconda3\lib\site-packages\cryptography\hazmat\backends__init__.pi line 15 default_backend cryptography.hazmat.backends.openssl.backend import backend file c:\users\selvam\appdata\local\continuum\anaconda3\lib\site-packages\cryptography\hazmat\backends\openssl__init__.pi line 7 cryptography.hazmat.backends.openssl.backend import backend file c:\users\selvam\appdata\local\continuum\anaconda3\lib\site-packages\cryptography\hazmat\backends\openssl\backend.pi line 53 cryptography.hazmat.bindings.openssl import bind file c:\users\selvam\appdata\local\continuum\anaconda3\lib\site-packages\cryptography\hazmat\bindings\openssl\binding.pi line 13 cryptography.hazmat.bindings._openssl import ffi lib importerror dll load fail specifi modul found line 168 connecthandl return connectionclass*arg **kwarg file c:\users\selvam\venv\lib\site-packages\netmiko\base_connection.pi line 187 init self.establish_connect file c:\users\selvam\venv\lib\site-packages\netmiko\base_connection.pi line 650 establish_connect self.remote_conn_pre.connect**ssh_connect_param file c:\users\selvam\venv\lib\site-packages\paramiko\client.pi line 392 connect t.start_clienttimeout=timeout file c:\users\selvam\venv\lib\site-packages\paramiko\transport.pi line 545 start_client rais e file c:\users\selvam\venv\lib\site-packages\paramiko\transport.pi line 1888 run self.kex_engine.parse_nextptyp file c:\users\selvam\venv\lib\site-packages\paramiko\kex_group1.pi line 75 parse_next return self._parse_kexdh_replym file c:\users\selvam\venv\lib\site-packages\paramiko\kex_group1.pi line 114 _parse_kexdh_repli self.transport._verify_keyhost_key sig file c:\users\selvam\venv\lib\site-packages\paramiko\transport.pi line 1747 _verify_key key = self._key_infoself.host_key_typ file c:\users\selvam\venv\lib\site-packages\paramiko\rsakey.pi line 62 init .public_keydefault_backend file c:\users\selvam\appdata\local\continuum\anaconda3\lib\site-packages\cryptography\hazmat\backends__init__.pi line 15 default_backend cryptography.hazmat.backends.openssl.backend import backend file c:\users\selvam\appdata\local\continuum\anaconda3\lib\site-packages\cryptography\hazmat\backends\openssl__init__.pi line 7 cryptography.hazmat.backends.openssl.backend import backend file c:\users\selvam\appdata\local\continuum\anaconda3\lib\site-packages\cryptography\hazmat\backends\openssl\backend.pi line 53 cryptography.hazmat.bindings.openssl import bind file c:\users\selvam\appdata\local\continuum\anaconda3\lib\site-packages\cryptography\hazmat\bindings\openssl\binding.pi line 13 cryptography.hazmat.bindings._openssl import ffi lib importerror dll load fail specifi modul found,0.1813953488372093,39,paramiko python,python unknown except dll load fail specifi modul found netmiko modul,5,scripting|transport|crypt|openssl|ssh,0.49313515424728394
hillclimb algo principl appli crypto work follow make key random 25 char alphabet make ramdom determin fit digraph score call ‘parent’ make chang parent produc ‘child’ key random swap 5x5 grid keytabl bad measur fit digraph score function child fitter parent make childth new parent dispens old go back 2 unless improv last 1000chang case go back 1 avoid block local maximum digraph score function want better result hillclimb must develop simul anneal algorithm score function base trigram 4-gram less local maximums.if want crack faster move python c/c++ hillclimb simul anneal algorithm use crack playfair cipher well 5*5 grid base cipher simpl substitut cipher vigener cipher import thing playfair cipher weak circular horizont vertic permut 5x5 grid equival key algo converg cipher faster make parent alphabet follow playfair deciph function sa algo find basic principl sa http://en.wikipedia.org/wiki/simulated_ann playfair cipher use us coast guard wwii famou histor playfair cipher http://practicalcryptography.com/ciphers/playfair-cipher/ ps name main charact playfair cipher exampl alic mutat gener recombin read question correctli mayb go gener 0 random key pick n highest rank key rest die crossbre survivor among low percentag mutat recombin rins repeat recombin look parent b produc n offspr offspr choos 0 &lt;= x &lt;= &lt 25 mayb constraint - x > c offspr key a[:x] + b[x:y] + a[y,2014-01-01 20:31:04.36 UTC,528,20872945,write python script crack playfair cipher ciphertext.first gener 30-100 decrypt key run ciphertext rank one digraph frequenc next gener /iter copi one best score mutat letter swap place 5x5 grid re-add next iter rank notic script often find local maximum - key give similar distribut yet real deal think solut problem introduc variat popul key end script almost tri implement ad gener coupl total random key elimin almost immedi better it? thought tactic simul anneal idea much help edit sampl ciphertext request key playfair exampl el ir ul vi ne uz qk dm kz qe ca qe tb qc pv zb md nv om lo gv qo od er qc zg pv vk ov iw zg ro nz ge ro af yp qe zi lo rk pr ad xl dl ix cl qr rk dq vu sa zb xv qe ho dm dn ok eb xe bm iz kd de kv ef kc rd lv om dm vy km ur et xe aq zb xe tx om rt gh rk hc fg mk py dr qo af zs xv nv ac df ad dl yr bm ef pm zs lo ce yl ai ca nv ca fy wi dm ov ne tx zb bm kn ul bn ar km uz fo ka ro gp lo kv dm ml qe zi lo rk pr ad xl tx zb le nv oc py dr lo ca le dx xa mo pr oi yp en dy oc dk zb kv ix ol pr dr oq pb dr gb eo ak vg xe df zb pv nl cr ya ad iu dm dm eo qm dm pu ad xl nl er nv kz qn oq yg df pb uz fo ya ay dk vu lo gd ex ip ya bp xv yf nv vk pz dm vq vo vk pr kz ro,0.04924242424242424,26,algorithm cryptography hill-climbing python,playfair hillclimb crack,4,crypt|crack|scripting|cipher,0.48569944500923157
github issu say basic navig applications/python 3.6/ folder doubl click instal certificates.command try run program 3.6 run instal certif command like solv issu,2019-12-19 14:05:06,275,59411362,use pycharm python 3.8 latest version discord tri run script got error anyon help? ------ error ------- /users/mellie/pycharmprojects/dominations/venv/bin/python /users/mellie/pycharmprojects/dominations/domi.pi traceback recent call last file /users/mellie/pycharmprojects/dominations/venv/lib/python3.8/site-packages/aiohttp/connector.pi line 936 _wrap_create_connect return await self._loop.create_connection*arg **kwarg # type ignor # noqa file /library/frameworks/python.framework/versions/3.8/lib/python3.8/asyncio/base_events.pi line 1042 create_connect transport protocol = await self._create_connection_transport file /library/frameworks/python.framework/versions/3.8/lib/python3.8/asyncio/base_events.pi line 1072 _create_connection_transport await waiter file /library/frameworks/python.framework/versions/3.8/lib/python3.8/asyncio/sslproto.pi line 529 data_receiv ssldata appdata = self._sslpipe.feed_ssldatadata file /library/frameworks/python.framework/versions/3.8/lib/python3.8/asyncio/sslproto.pi line 189 feed_ssldata self._sslobj.do_handshak file /library/frameworks/python.framework/versions/3.8/lib/python3.8/ssl.pi line 944 do_handshak self._sslobj.do_handshak ssl.sslcertverificationerror [ssl certificate_verify_failed] certif verifi fail unabl local issuer certif _ssl.c:1108 except direct caus follow except traceback recent call last file /users/mellie/pycharmprojects/dominations/domi.pi line 24 client.runtoken file /users/mellie/pycharmprojects/dominations/venv/lib/python3.8/site-packages/discord/client.pi line 640 run return future.result file /users/mellie/pycharmprojects/dominations/venv/lib/python3.8/site-packages/discord/client.pi line 621 runner await self.start*arg **kwarg file /users/mellie/pycharmprojects/dominations/venv/lib/python3.8/site-packages/discord/client.pi line 584 start await self.login*arg bot=bot file /users/mellie/pycharmprojects/dominations/venv/lib/python3.8/site-packages/discord/client.pi line 442 login await self.http.static_logintoken.strip bot=bot file /users/mellie/pycharmprojects/dominations/venv/lib/python3.8/site-packages/discord/http.pi line 256 static_login data = await self.requestrout /users/@m file /users/mellie/pycharmprojects/dominations/venv/lib/python3.8/site-packages/discord/http.pi line 160 request async self session.requestmethod url **kwarg r file /users/mellie/pycharmprojects/dominations/venv/lib/python3.8/site-packages/aiohttp/client.pi line 1012 __aenter self._resp = await self._coro file /users/mellie/pycharmprojects/dominations/venv/lib/python3.8/site-packages/aiohttp/client.pi line 480 _request conn = await self._connector.connect file /users/mellie/pycharmprojects/dominations/venv/lib/python3.8/site-packages/aiohttp/connector.pi line 523 connect proto = await self._create_connectionreq trace timeout file /users/mellie/pycharmprojects/dominations/venv/lib/python3.8/site-packages/aiohttp/connector.pi line 858 _create_connect _ proto = await self._create_direct_connect file /users/mellie/pycharmprojects/dominations/venv/lib/python3.8/site-packages/aiohttp/connector.pi line 1004 _create_direct_connect rais last_exc file /users/mellie/pycharmprojects/dominations/venv/lib/python3.8/site-packages/aiohttp/connector.pi line 980 _create_direct_connect transp proto = await self._wrap_create_connect file /users/mellie/pycharmprojects/dominations/venv/lib/python3.8/site-packages/aiohttp/connector.pi line 938 _wrap_create_connect rais clientconnectorcertificateerror aiohttp.client_exceptions.clientconnectorcertificateerror cannot connect host discordapp.com:443 ssl:true [sslcertverificationerror 1 [ssl certificate_verify_failed] certif verifi fail unabl local issuer certif _ssl.c:1108 ] process finish exit code 1,0.14545454545454545,40,discord.py python,ssl certificate_verify_failed] certif verifi fail unabl local issuer certif _ssl.c:1108 discord/python,5,ssl|certificate|scripting|transport|login,0.46295052766799927
use self-sign certificate? add command self-sign certif ca sign pass --no-verifi option bypass ca verif self-sign certif ca sign pass --no-verifi option bypass ca verif sourc,2018-02-19 11:32:19.803 UTC,395,48865292,tri connect secur azur servic fabric cluster mac ssl issu authent /explor certif via web browser tri command-lin get ssl errors.ani suggest pleas ? error error occur request sslerror httpsconnectionpoolhost= mylinuxx.centralindia.cloudapp.azure.com port=19080 max retri exceed url / caus sslerrorsslerror1 [ssl certificate_verify_failed] certif verifi fail _ssl.c:777 traceback recent call last file /usr/local/lib/python3.6/site-packages/urllib3/connectionpool.pi line 601 urlopen chunked=chunk file /usr/local/lib/python3.6/site-packages/urllib3/connectionpool.pi line 346 _make_request self._validate_connconn file /usr/local/lib/python3.6/site-packages/urllib3/connectionpool.pi line 850 _validate_conn conn.connect file /usr/local/lib/python3.6/site-packages/urllib3/connection.pi line 326 connect ssl_context=context file /usr/local/lib/python3.6/site-packages/urllib3/util/ssl_.pi line 329 ssl_wrap_socket return context.wrap_socketsock server_hostname=server_hostnam file /usr/local/cellar/python3/3.6.4_2/frameworks/python.framework/versions/3.6/lib/python3.6/ssl.pi line 407 wrap_socket _context=self _session=sess file /usr/local/cellar/python3/3.6.4_2/frameworks/python.framework/versions/3.6/lib/python3.6/ssl.pi line 814 init self.do_handshak file /usr/local/cellar/python3/3.6.4_2/frameworks/python.framework/versions/3.6/lib/python3.6/ssl.pi line 1068 do_handshak self._sslobj.do_handshak file /usr/local/cellar/python3/3.6.4_2/frameworks/python.framework/versions/3.6/lib/python3.6/ssl.pi line 689 do_handshak self._sslobj.do_handshak ssl.sslerror [ssl certificate_verify_failed] certif verifi fail _ssl.c:777 handl except anoth except occur traceback recent call last file /usr/local/lib/python3.6/site-packages/requests/adapters.pi line 440 send timeout=timeout file /usr/local/lib/python3.6/site-packages/urllib3/connectionpool.pi line 668 urlopen **response_kw file /usr/local/lib/python3.6/site-packages/urllib3/connectionpool.pi line 668 urlopen **response_kw file /usr/local/lib/python3.6/site-packages/urllib3/connectionpool.pi line 668 urlopen **response_kw file /usr/local/lib/python3.6/site-packages/urllib3/connectionpool.pi line 639 urlopen _stacktrace=sys.exc_info[2] file /usr/local/lib/python3.6/site-packages/urllib3/util/retry.pi line 388 increment rais maxretryerror_pool url error responseerrorcaus urllib3.exceptions.maxretryerror httpsconnectionpoolhost= mylinuxx.centralindia.cloudapp.azure.com port=19080 max retri exceed url / caus sslerrorsslerror1 [ssl certificate_verify_failed] certif verifi fail _ssl.c:777 handl except anoth except occur traceback recent call last file /usr/local/lib/python3.6/site-packages/msrest/service_client.pi line 201 send **kwarg file /usr/local/lib/python3.6/site-packages/requests/sessions.pi line 508 request resp = self.sendprep **send_kwarg file /usr/local/lib/python3.6/site-packages/requests/sessions.pi line 618 send r = adapter.sendrequest **kwarg file /usr/local/lib/python3.6/site-packages/requests/adapters.pi line 506 send rais sslerror request=request requests.exceptions.sslerror httpsconnectionpoolhost= mylinuxx.centralindia.cloudapp.azure.com port=19080 max retri exceed url / caus sslerrorsslerror1 [ssl certificate_verify_failed] certif verifi fail _ssl.c:777 handl except anoth except occur traceback recent call last file /usr/local/lib/python3.6/site-packages/knack/cli.pi line 125 invok cmd_result = self.invocation.executearg file /usr/local/lib/python3.6/site-packages/knack/invocation.pi line 85 execut cmd_result = parsed_args.funcparam file /usr/local/lib/python3.6/site-packages/knack/commands.pi line 67 call return self.handler*arg **kwarg file /usr/local/lib/python3.6/site-packages/knack/commands.pi line 123 _command_handl result = opclient **command_arg client els op**command_arg file /usr/local/lib/python3.6/site-packages/sfctl/custom_cluster.pi line 95 select rest_client.sendrest_client.get / .raise_for_statu file /usr/local/lib/python3.6/site-packages/msrest/service_client.pi line 227 send raise_with_tracebackclientrequesterror msg err file /usr/local/lib/python3.6/site-packages/msrest/exceptions.pi line 45 raise_with_traceback rais error.with_tracebackexc_traceback file /usr/local/lib/python3.6/site-packages/msrest/service_client.pi line 201 send **kwarg file /usr/local/lib/python3.6/site-packages/requests/sessions.pi line 508 request resp = self.sendprep **send_kwarg file /usr/local/lib/python3.6/site-packages/requests/sessions.pi line 618 send r = adapter.sendrequest **kwarg file /usr/local/lib/python3.6/site-packages/requests/adapters.pi line 506 send rais sslerror request=request msrest.exceptions.clientrequesterror error occur request sslerror httpsconnectionpoolhost= mylinuxx.centralindia.cloudapp.azure.com port=19080 max retri exceed url / caus sslerrorsslerror1 [ssl certificate_verify_failed] certif verifi fail _ssl.c:777,0.15443037974683543,61,azure azure-cli azure-service-fabric python-3.x,unabl connect azur servic fabric cluster mac,7,security|ssl|authentication|certificate|validate|signing|bypass,0.4614487290382385
,2018-11-29 03:26:41.753 UTC,50,53531420,"tri login servic ,a error rais look authent success code 2.that error traceback recent call last file line 1 file /data/ai-aomt/venv/lib/python2.7/site-packages/exscript/protocols/protocol.pi line 674 login file /data/ai-aomt/venv/lib/python2.7/site-packages/exscript/protocols/protocol.pi line 699 authent file /data/ai-aomt/venv/lib/python2.7/site-packages/exscript/protocols/protocol.pi line 868 app_authent file /data/ai-aomt/venv/lib/python2.7/site-packages/exscript/protocols/protocol.pi line 772 _app_authent exscript.protocols.exception.timeoutexcept buffer u",0.32,16,exscript login-script python ssh,python ssh2 connect timeout,4,scripting|login|ssh|authentication,0.4513445496559143
updat sinc latest develop version scapi field get decod properli look github version https://github.com/secdev/scapi download https://github.com/secdev/scapy/archive/master.zip field name let guess contain data cannot decod realli want decod either write mayb contribute! dissector wireshark tshark dissector command line interfac pars packet second option scapi wireshark tshark decod 802.11 frame scapi first captur 802.11 frame whether termin wireshark save pcap file scapi pars pcap file pars custom function process frame pcap file mine see dot11 frame attribut scapi python - 802.11 ds statu,2017-11-10 17:22:33.893 UTC,120,47228102,write program captur dot11 packet network secur test captur packet data follow exampl better understand part read type packet mani differ captur want abl decod read data perhap code sampl,0.06666666666666667,8,network-security networking python scapy,decod data scapi dot11 packet,2,security|decode,0.4387524425983429
,2013-04-12 08:39:11.017 UTC,131,15966743,"tri perform authent domain level googl drive apioauth2 refer googl drive document link https://developers.google.com/drive/deleg alreadi instal openssl error importerror cannot import name signedjwtasseioncredenti tri import signedjwtassertioncredenti full traceback follow error 2013-04-16 05:03:52,006 wsgi.py:219] traceback recent call last file c:\program files\google\google_appengine\google\appengine\runtime\wsgi.pi line 196 handl handler = _config_handle.add_wsgi_middlewareself._loadhandl file c:\program files\google\google_appengine\google\appengine\runtime\wsgi.pi line 255 _loadhandl handler = import path[0] file c:\program files\google\google_appengine\google\appengine\tools\dev_appserver_import_hook.pi line 692 decor return funcself *arg **kwarg file c:\program files\google\google_appengine\google\appengine\tools\dev_appserver_import_hook.pi line 1766 load_modul return self.findandloadmodulesubmodul fullnam search_path file c:\program files\google\google_appengine\google\appengine\tools\dev_appserver_import_hook.pi line 692 decor return funcself *arg **kwarg file c:\program files\google\google_appengine\google\appengine\tools\dev_appserver_import_hook.pi line 1630 findandloadmodul descript file c:\program files\google\google_appengine\google\appengine\tools\dev_appserver_import_hook.pi line 692 decor return funcself *arg **kwarg file c:\program files\google\google_appengine\google\appengine\tools\dev_appserver_import_hook.pi line 1577 loadmodulerestrict descript file d:\api\googledrive\myapp\main.pi line 21 oauth2client.cli import signedjwtassertioncredentialsimporterror cannot import name signedjwtassertioncredenti anyon tell solut",0.12213740458015267,16,google-drive-api pyopenssl python,googl drive api importerror,7,openssl|authentication|oauth|delegation|signing|credential|scripting,0.43482911586761475
avoid open file rb file object f clearli use encoding? encod specifi use decod content iter content alreadi convert text python interfac directli open file mode drop encod point decod text first thing order transport content encod back byte,2017-11-27 20:47:55.417 UTC,143,47519548,troubl figur file content delet later load encod caus except botocor hash produc deletem put traceback recent call last file ./test_operator.pi line 41 key= testing/a/put file /users/lamblin/venvs/awscli/lib/python3.6/site-packages/botocore/client.pi line 312 _api_cal return self._make_api_calloperation_nam kwarg file /users/lamblin/venvs/awscli/lib/python3.6/site-packages/botocore/client.pi line 582 _make_api_cal request_signer=self._request_sign context=request_context file /users/lamblin/venvs/awscli/lib/python3.6/site-packages/botocore/hooks.pi line 242 emit_until_respons respons = self._emitevent_nam kwarg stop_on_response=tru file /users/lamblin/venvs/awscli/lib/python3.6/site-packages/botocore/hooks.pi line 210 _emit respons = handler**kwarg file /users/lamblin/venvs/awscli/lib/python3.6/site-packages/botocore/handlers.pi line 201 conditionally_calculate_md5 calculate_md5param **kwarg file /users/lamblin/venvs/awscli/lib/python3.6/site-packages/botocore/handlers.pi line 179 calculate_md5 binary_md5 = _calculate_md5_from_filebodi file /users/lamblin/venvs/awscli/lib/python3.6/site-packages/botocore/handlers.pi line 193 _calculate_md5_from_fil md5.updatechunk typeerror unicode-object must encod hash avoid open file rb file object clearli use encod,0.16083916083916083,23,amazon-s3 botocore python,botocor s3 put issu hash file due encod,6,hash|encode|signing|md5|decode|transport,0.4227549731731415
found answer went python3.8 folder instal someth call instal certif command fix ssl error thank,2019-12-03 23:10:50,214,59166761,tri play hashcrack secur sandbox account ethic purpos believ code correct cannot find reason execut well code clearli correct unless run lol howev cannot find bug error traceback traceback recent call last file hashcracker.pi line 5 list_of_common_password = strurlopen https://raw.githubusercontent.com/danielmiessler/seclists/master/passwords/common-credentials/10-million-password-list-top-10000.txt .read utf-8 file /library/frameworks/python.framework/versions/3.8/lib/python3.8/urllib/request.pi line 222 urlopen return opener.openurl data timeout file /library/frameworks/python.framework/versions/3.8/lib/python3.8/urllib/request.pi line 525 open respons = self._openreq data file /library/frameworks/python.framework/versions/3.8/lib/python3.8/urllib/request.pi line 542 _open result = self._call_chainself.handle_open protocol protocol + file /library/frameworks/python.framework/versions/3.8/lib/python3.8/urllib/request.pi line 502 _call_chain result = func*arg file /library/frameworks/python.framework/versions/3.8/lib/python3.8/urllib/request.pi line 1360 https_open return self.do_openhttp.client.httpsconnect req file /library/frameworks/python.framework/versions/3.8/lib/python3.8/urllib/request.pi line 1320 do_open rais urlerrorerrurllib.error.urlerror mbp-00704:sha1crack andrewroe$ python3 hashcracker.pi pleas input hash crack cbfdac6008f9cab4083784cbd1874f76618d2a97 traceback recent call last file /library/frameworks/python.framework/versions/3.8/lib/python3.8/urllib/request.pi line 1317 do_open h.requestreq.get_method req.selector req.data header file /library/frameworks/python.framework/versions/3.8/lib/python3.8/http/client.pi line 1230 request self._send_requestmethod url bodi header encode_chunk file /library/frameworks/python.framework/versions/3.8/lib/python3.8/http/client.pi line 1276 _send_request self.endheadersbodi encode_chunked=encode_chunk file /library/frameworks/python.framework/versions/3.8/lib/python3.8/http/client.pi line 1225 endhead self._send_outputmessage_bodi encode_chunked=encode_chunk file /library/frameworks/python.framework/versions/3.8/lib/python3.8/http/client.pi line 1004 _send_output self.sendmsg file /library/frameworks/python.framework/versions/3.8/lib/python3.8/http/client.pi line 944 send self.connect file /library/frameworks/python.framework/versions/3.8/lib/python3.8/http/client.pi line 1399 connect self.sock = self._context.wrap_socketself.sock file /library/frameworks/python.framework/versions/3.8/lib/python3.8/ssl.pi line 500 wrap_socket return self.sslsocket_class._cr file /library/frameworks/python.framework/versions/3.8/lib/python3.8/ssl.pi line 1040 _creat self.do_handshak file /library/frameworks/python.framework/versions/3.8/lib/python3.8/ssl.pi line 1309 do_handshak self._sslobj.do_handshak ssl.sslcertverificationerror [ssl certificate_verify_failed] certif verifi fail unabl local issuer certif _ssl.c:1108 handl except anoth except occur,0.16822429906542055,36,python,hashlib troubl debug,9,hash|crack|security|sandbox|password|ssl|credential|encode|certificate,0.40651047229766846
occur use probabl older version eclips helio got problem switch kepler version error vanish hope help,2014-06-05 07:56:03.57 UTC,403,24054660,"tri instal pydev ubuntu 12.4.04 follow instruct .when select pydev packag among eclips packag list eclips tell cannot complet instal one requir item found softwar instal pydev mylyn integr 0.4.0 org.python.pydev.mylyn.feature.feature.group 0.4.0 miss requir pydev mylyn integr 0.4.0 org.python.pydev.mylyn.feature.feature.group 0.4.0 requir org.eclipse.mylyn.context.cor 0.0.0 found know solv this? edit select avail download websit option start download got new error error occur collect item instal session context was:profile=platformprofil phase=org.eclipse.equinox.internal.p2.engine.phases.collect operand= action= problem download artifact osgi.bundle,com.python.pydev,3.5.0.201405201709 error read sign content:/tmp/signaturefile8427466212879929206.jar error occur process signatur file /tmp/signaturefile8427466212879929206.jar problem download artifact osgi.bundle,com.python.pydev.analysis,3.5.0.201405201709 error read sign content:/tmp/signaturefile6225334791154145595.jar error occur process signatur file /tmp/signaturefile6225334791154145595.jar problem download artifact osgi.bundle,com.python.pydev.codecompletion,3.5.0.201405201709 error read sign content:/tmp/signaturefile1625250666117296864.jar error occur process signatur file /tmp/signaturefile1625250666117296864.jar problem download artifact osgi.bundle,com.python.pydev.debug,3.5.0.201405201709 error read sign content:/tmp/signaturefile5513082187501911158.jar error occur process signatur file /tmp/signaturefile5513082187501911158.jar problem download artifact osgi.bundle,com.python.pydev.fastparser,3.5.0.201405201709 error read sign content:/tmp/signaturefile605486589496460440.jar error occur process signatur file /tmp/signaturefile605486589496460440.jar problem download artifact osgi.bundle,com.python.pydev.refactoring,3.5.0.201405201709 error read sign content:/tmp/signaturefile144672797460509165.jar error occur process signatur file /tmp/signaturefile144672797460509165.jar problem download artifact osgi.bundle,org.python.pydev,3.5.0.201405201709 error read sign content:/tmp/signaturefile6260050602791980202.jar error occur process signatur file /tmp/signaturefile6260050602791980202.jar problem download artifact osgi.bundle,org.python.pydev.ast,3.5.0.201405201709 error read sign content:/tmp/signaturefile7925013072583879479.jar error occur process signatur file /tmp/signaturefile7925013072583879479.jar problem download artifact osgi.bundle,org.python.pydev.core,3.5.0.201405201709 error read sign content:/tmp/signaturefile6502114115388448316.jar error occur process signatur file /tmp/signaturefile6502114115388448316.jar problem download artifact osgi.bundle,org.python.pydev.customizations,3.5.0.201405201709 error read sign content:/tmp/signaturefile646114539488211012.jar error occur process signatur file /tmp/signaturefile646114539488211012.jar problem download artifact osgi.bundle,org.python.pydev.debug,3.5.0.201405201709 error read sign content:/tmp/signaturefile5554172731601599412.jar error occur process signatur file /tmp/signaturefile5554172731601599412.jar problem download artifact osgi.bundle,org.python.pydev.django,3.5.0.201405201709 error read sign content:/tmp/signaturefile2081112544030499068.jar error occur process signatur file /tmp/signaturefile2081112544030499068.jar problem download artifact org.eclipse.update.feature,org.python.pydev.feature,3.5.0.201405201709 error read sign content:/tmp/signaturefile8761783145012931325.jar error occur process signatur file /tmp/signaturefile8761783145012931325.jar problem download artifact osgi.bundle,org.python.pydev.help,3.5.0.201405201709 error read sign content:/tmp/signaturefile4140872971434327198.jar error occur process signatur file /tmp/signaturefile4140872971434327198.jar problem download artifact osgi.bundle,org.python.pydev.jython,3.5.0.201405201709 error read sign content:/tmp/signaturefile1472620833557689910.jar error occur process signatur file /tmp/signaturefile1472620833557689910.jar problem download artifact osgi.bundle,org.python.pydev.mylyn,0.4.0 error read sign content:/tmp/signaturefile6287310346304363477.jar error occur process signatur file /tmp/signaturefile6287310346304363477.jar problem download artifact org.eclipse.update.feature,org.python.pydev.mylyn.feature,0.4.0 error read sign content:/tmp/signaturefile2932536020816821753.jar error occur process signatur file /tmp/signaturefile2932536020816821753.jar problem download artifact osgi.bundle,org.python.pydev.parser,3.5.0.201405201709 error read sign content:/tmp/signaturefile2860560593863228850.jar error occur process signatur file /tmp/signaturefile2860560593863228850.jar problem download artifact osgi.bundle,org.python.pydev.refactoring,3.5.0.201405201709 error read sign content:/tmp/signaturefile5444565411686316987.jar error occur process signatur file /tmp/signaturefile5444565411686316987.jar problem download artifact osgi.bundle,org.python.pydev.shared_core,3.5.0.201405201709 error read sign content:/tmp/signaturefile644095121866711816.jar error occur process signatur file /tmp/signaturefile644095121866711816.jar problem download artifact osgi.bundle,org.python.pydev.shared_interactive_console,3.5.0.201405201709 error read sign content:/tmp/signaturefile708235382114637181.jar error occur process signatur file /tmp/signaturefile708235382114637181.jar problem download artifact osgi.bundle,org.python.pydev.shared_ui,3.5.0.201405201709 error read sign content:/tmp/signaturefile8183417620218922292.jar error occur process signatur file /tmp/signaturefile8183417620218922292.jar",0.22580645161290322,91,eclipse eclipse-plugin pydev python,eclips miss requir eclips packag instal,4,integrity|availability|signing|signature,0.40592366456985474
,2018-07-30 10:19:11.32 UTC,124,51591776,new python.and tri mitmdump crawl app mongodb store datu but...i found answer googl got idea do. windows10 platform assum whether window doesnt support d:\users\administrator\desktop\python>mitmdump -s scriptstest.pi load script scriptstest.pi addon error traceback recent call last file c:\users\administrator\appdata\roaming\python\python36\site- packages\mitmproxy\addonmanager.pi line 42 safecal yield file c:\users\administrator\appdata\roaming\python\python36\site- packages\mitmproxy\addons\script.pi line 102 loadscript ctx.master.addons.registern file c:\users\administrator\appdata\roaming\python\python36\site- packages\mitmproxy\addonmanager.pi line 161 regist self.master.commands.collect_commandsa file c:\users\administrator\appdata\roaming\python\python36\site- packages\mitmproxy\command.pi line 144 collect_command self.addo.command_path file c:\users\administrator\appdata\roaming\python\python36\site- packages\mitmproxy\command.pi line 151 add self.commands[path] = commandself path func file c:\users\administrator\appdata\roaming\python\python36\site- packages\mitmproxy\command.pi line 51 init sig = inspect.signatureself.func file d:\users\administrator\anaconda3\lib\inspect.pi line 3033 signatur return signature.from_callableobj follow_wrapped=follow_wrap file d:\users\administrator\anaconda3\lib\inspect.pi line 2783 from_cal follow_wrapper_chains=follow_wrap file d:\users\administrator\anaconda3\lib\inspect.pi line 2183 _signature_from_cal rais typeerror {!r} callabl object .formatobj typeerror mongoclienthost=[ 127.0.0.1:27017 ] document_class=dict tz_aware=fals connect=tru callabl object script code,0.16129032258064516,20,python python-3.x,mitmdump work pymongo,4,mitm|scripting|safe|signature,0.3893583416938782
instal certif either double-click file maco run command termin certif instal download data http sourc dedic issu tensorflow github offici model replac http http got run contrib/learn/python/learn/datasets/mnist.pi edit line withsource_url= http://storage.googleapis.com/cvdf-datasets/mnist,2017-10-20 23:34:36.647 UTC,263,46858630,tri download mnist data supposedli handl tensorflow.examples.tutorials.mnist.input_data.read_data_set far awar read_data_set send pull request server download approx 1.5gb data keep get traceback error file /library/frameworks/python.framework/versions/3.6/lib/python3.6/urllib/request.pi line 1318 do_open encode_chunked=req.has_head transfer-encod file /library/frameworks/python.framework/versions/3.6/lib/python3.6/http/client.pi line 1239 request self._send_requestmethod url bodi header encode_chunk file /library/frameworks/python.framework/versions/3.6/lib/python3.6/http/client.pi line 1285 _send_request self.endheadersbodi encode_chunked=encode_chunk file /library/frameworks/python.framework/versions/3.6/lib/python3.6/http/client.pi line 1234 endhead self._send_outputmessage_bodi encode_chunked=encode_chunk file /library/frameworks/python.framework/versions/3.6/lib/python3.6/http/client.pi line 1026 _send_output self.sendmsg file /library/frameworks/python.framework/versions/3.6/lib/python3.6/http/client.pi line 964 send self.connect file /library/frameworks/python.framework/versions/3.6/lib/python3.6/http/client.pi line 1400 connect server_hostname=server_hostnam file /library/frameworks/python.framework/versions/3.6/lib/python3.6/ssl.pi line 401 wrap_socket _context=self _session=sess file /library/frameworks/python.framework/versions/3.6/lib/python3.6/ssl.pi line 808 init self.do_handshak file /library/frameworks/python.framework/versions/3.6/lib/python3.6/ssl.pi line 1061 do_handshak self._sslobj.do_handshak file /library/frameworks/python.framework/versions/3.6/lib/python3.6/ssl.pi line 683 do_handshak self._sslobj.do_handshak ssl.sslerror [ssl certificate_verify_failed] certif verifi fail _ssl.c:748 obvious someth ssl cert python uses. went /applications/python 3.6/ execut instal certifactions.command locat got error traceback recent call last file /library/frameworks/python.framework/versions/3.6/lib/python3.6/shutil.pi line 544 move os.renamesrc real_dst permissionerror [errno 13] permiss deni /library/frameworks/python.framework/versions/3.6/lib/python3.6/site-packages/certifi-2015.04.28.dist-info/description.rst -> /var/folders/mq/g_jy_1qx1vjdb3xmdh7y62y80000gn/t/pip-3m8ixnf5-uninstall/library/frameworks/python.framework/versions/3.6/lib/python3.6/site-packages/certifi-2015.04.28.dist-info/description.rst handl except anoth except occur traceback recent call last file /library/frameworks/python.framework/versions/3.6/lib/python3.6/site-packages/pip/basecommand.pi line 215 main statu = self.runopt arg file /library/frameworks/python.framework/versions/3.6/lib/python3.6/site-packages/pip/commands/install.pi line 342 run prefix=options.prefix_path file /library/frameworks/python.framework/versions/3.6/lib/python3.6/site-packages/pip/req/req_set.pi line 778 instal requirement.uninstallauto_confirm=tru file /library/frameworks/python.framework/versions/3.6/lib/python3.6/site-packages/pip/req/req_install.pi line 754 uninstal paths_to_remove.removeauto_confirm file /library/frameworks/python.framework/versions/3.6/lib/python3.6/site-packages/pip/req/req_uninstall.pi line 115 remov renamespath new_path file /library/frameworks/python.framework/versions/3.6/lib/python3.6/site-packages/pip/utils/ init .py line 267 renam shutil.moveold new file /library/frameworks/python.framework/versions/3.6/lib/python3.6/shutil.pi line 559 move os.unlinksrc permissionerror [errno 13] permiss deni /library/frameworks/python.framework/versions/3.6/lib/python3.6/site-packages/certifi-2015.04.28.dist-info/description.rst someth wrong filesystem permissions? quit liter reinstal osx month ago computer. manual instal certs? issu pull request download data non-http address,0.12167300380228137,32,download mnist python ssl tensorflow,python ssl certif problem tensorflow,4,ssl|certificate|encode|scripting,0.38218262791633606
server-sid encrypt enabl turn encrypt rest mean file encrypt sit s3 s3 decrypt file send data download file chang handl file download file encrypt type encrypt protect file file download via valid mean use api protect file read someon circumv s3 data center someth need protect file must decrypt download need encrypt client-sid upload s3 client-sid encrypt scheme deem worthi aes256 etc s3,2017-02-01 18:34:52.297 UTC,135,41987133,use s3 instead kms store essenti credenti file python read file content manual file encrypt click s3 go properti - detail - server side encryption:aes-256 python script read key without make chang read file unencrypt abl download file open without anyth decrypt expect decrypt littl confus unabl understand server-sid encrypt protect anyon alreadi access s3 s3 bucket key/fil abl read file? abl open file,0.2,27,amazon-s3 amazon-web-services encryption python,ever decrypt s3-encrypt file,7,encrypt|crypt|credential|aes|scripting|protect|validate,0.37313735485076904
flag true disabl automat file delet occur upon fail viru scan although googlechrom browser window still see viru scan fail download file nonetheless file stay download folder howev want,2017-09-14 21:56:06.58 UTC,106,46228816,download excel file websit via python script via googl chrome reason download file fail viru scan delet immedi without prompt know safe file manual download alway pass viru scan disabl viru scan googl chrome within python script script start enabl viru scan upon finish? follow prefer set chromedriv link list prefer option avail selenium chromedriv find viru scan upon download option list https://cs.chromium.org/chromium/src/chrome/common/pref_names.cc,0.14150943396226415,15,google-chrome python selenium selenium-chromedriver virus-scanning,disabl viru scan googl chrome insid python script download,4,virus|scripting|safe|availability,0.37081941962242126
,2014-11-08 07:00:01.063 UTC,228,26814696,"app engin app use oauth rauth tri facebook twitter googl login run local work product got error googl plu facebook work fine connect abort error13 permiss deni traceback recent call last file /base/data/home/runtimes/python27/python27_lib/versions/third_party/webapp2-2.5.2/webapp2.pi line 1535 call rv = self.handle_exceptionrequest respons e file /base/data/home/runtimes/python27/python27_lib/versions/third_party/webapp2-2.5.2/webapp2.pi line 1529 call rv = self.router.dispatchrequest respons file /base/data/home/runtimes/python27/python27_lib/versions/third_party/webapp2-2.5.2/webapp2.pi line 1278 default_dispatch return route.handler_adapterrequest respons file /base/data/home/runtimes/python27/python27_lib/versions/third_party/webapp2-2.5.2/webapp2.pi line 1102 call return handler.dispatch file /base/data/home/apps/s~app-getwell/login:1.379942143707124638/handler.pi line 11 dispatch webapp2.requesthandler.dispatchself file /base/data/home/runtimes/python27/python27_lib/versions/third_party/webapp2-2.5.2/webapp2.pi line 572 dispatch return self.handle_exception self.app.debug file /base/data/home/runtimes/python27/python27_lib/versions/third_party/webapp2-2.5.2/webapp2.pi line 570 dispatch return method*arg **kwarg file /base/data/home/apps/s~app-getwell/login:1.379942143707124638/logintoken.pi line 69 ep=log.gettokendatacod file /base/data/home/apps/s~app-getwell/login:1.379942143707124638/code/oauth/conect.pi line 34 gettokendata session = self.getsessionconf,cod file /base/data/home/apps/s~app-getwell/login:1.379942143707124638/code/oauth/conect.pi line 61 getsess session=conf.get_auth_sessiondata=self.getdatacod decoder=json.load file /base/data/home/apps/s~app-getwell/login:1.379942143707124638/code/oauth/rauth/service.pi line 556 get_auth_sess session = self.get_sessionself.get_access_tokenmethod **kwarg file /base/data/home/apps/s~app-getwell/login:1.379942143707124638/code/oauth/rauth/service.pi line 541 get_access_token r = self.get_raw_access_tokenmethod **kwarg file /base/data/home/apps/s~app-getwell/login:1.379942143707124638/code/oauth/rauth/service.pi line 518 get_raw_access_token **kwarg file /base/data/home/apps/s~app-getwell/login:1.379942143707124638/code/oauth/rauth/session.pi line 358 request return superoauth2sess self.requestmethod url **req_kwarg file /base/data/home/apps/s~app-getwell/login:1.379942143707124638/code/oauth/rauth/requests/sessions.pi line 457 request resp = self.sendprep **send_kwarg file /base/data/home/apps/s~app-getwell/login:1.379942143707124638/code/oauth/rauth/requests/sessions.pi line 569 send r = adapter.sendrequest **kwarg file /base/data/home/apps/s~app-getwell/login:1.379942143707124638/code/oauth/rauth/requests/adapters.pi line 407 send rais connectionerrorerr request=request connectionerror connect abort error13 permiss deni bill enabl yaml ad ssl librari latest code wich make oauth call code got secret key said strang work fine facebook fail googl plu dobl check client_id client_secret correct problem socket facebook fail ps.i copi rauth file project request file insid rauth folder",0.12280701754385964,28,google-app-engine google-plus oauth-2.0 python rauth,error use rauth app engin permiss deni,4,oauth|login|decode|ssl,0.3602624833583832
,2017-09-14 11:42:33.86 UTC,42,46218183,write file python content file encod form secur hashnot mean full code abl decod file content file? creat project need secur write file encrypt convert content non mean-abl content.and run program abl access content file,0.19047619047619047,8,hash python python-3.x,encod content file python,5,hash|encode|security|decode|encrypt,0.33120784163475037
return instead hash code,2016-09-23 01:39:16.133 UTC,67,39651277,current attempt download two file use python one gzip file checksum verifi gzip file content match md5 checksum save content target directori found download file learn calcul checksum load url json config file learn pars json file valu put togeth follow script stuck attempt store verifi content gzip file,0.13432835820895522,9,download gzip io md5 python,download gzip file md5 checksum save extract data match,4,md5|checksum|scripting|hash,0.3309873342514038
try use librari support password-protect archiv,2018-10-04 21:16:54.543 UTC,39,52655258,patoolib use extra content rar file case test.rar file password 123 give password argument extract_arch call? find anyth documentation.i altern lib,0.1794871794871795,7,compression extract passwords python rar,extract content encrypt rar file given password,3,password|encrypt|protect,0.3174637258052826
,2019-06-17 13:36:35.46 UTC,84,56632481,client provid huge pgp encrypt gz file around 20 gb sftp provid privat key.priv.asc ec2 local requir transfer file sftp aws s3 use aws transfer sftp servic load file aws s3 want decrypt unzip file process someon pleas help decrypt pgp file key present ec2 local note one approach load data ec2 first decrypt unzip load data s3 tri process unzip file size becom around 80gb take much time upload s3 want avoid approach,0.16666666666666666,14,amazon-s3 aws-lambda pgp python sftp,decrypt pgp file aws s3,5,pgp|sftp|crypt|encrypt|private key,0.31418707966804504
@contextlib.contextmanag decor request modul instead much simpler approach code work fine code gener partial method requests.session.request filter warn say hope help pleas let know case find better solut type byte rather str python doc class urllib.request.request . . http post request method data buffer standard application/x-www-form-urlencod format urllib.parse.urlencod function take map sequenc 2-tupl return ascii string format encod byte use data paramet . convert byte use method detail python urllib howto separ ssl valid issu presum attempt post data http connect success establish,2017-11-10 05:36:38.737 UTC,410,47216281,need post data rest interfac howev receiv host use self-sign certif chang need ignor obviou certif valid error receiv initi script look mention gener follow stacktrac traceback recent call last file c:\users\myusername\appdata\local\programs\python\python36\lib\urllib\request.pi line 1318 do_open encode_chunked=req.has_head transfer-encod file c:\users\myusername\appdata\local\programs\python\python36\lib\http\client.pi line 1239 request self._send_requestmethod url bodi header encode_chunk file c:\users\myusername\appdata\local\programs\python\python36\lib\http\client.pi line 1285 _send_request self.endheadersbodi encode_chunked=encode_chunk file c:\users\myusername\appdata\local\programs\python\python36\lib\http\client.pi line 1234 endhead self._send_outputmessage_bodi encode_chunked=encode_chunk file c:\users\myusername\appdata\local\programs\python\python36\lib\http\client.pi line 1026 _send_output self.sendmsg file c:\users\myusername\appdata\local\programs\python\python36\lib\http\client.pi line 964 send self.connect file c:\users\myusername\appdata\local\programs\python\python36\lib\http\client.pi line 1400 connect server_hostname=server_hostnam file c:\users\myusername\appdata\local\programs\python\python36\lib\ssl.pi line 407 wrap_socket _context=self _session=sess file c:\users\myusername\appdata\local\programs\python\python36\lib\ssl.pi line 814 init self.do_handshak file c:\users\myusername\appdata\local\programs\python\python36\lib\ssl.pi line 1068 do_handshak self._sslobj.do_handshak file c:\users\myusername\appdata\local\programs\python\python36\lib\ssl.pi line 689 do_handshak self._sslobj.do_handshak ssl.sslerror [ssl certificate_verify_failed] certif verifi fail _ssl.c:777 handl except anoth except occur traceback recent call last file send_data.pi line 16 urlopenpost_it_alreadi file c:\users\myusername\appdata\local\programs\python\python36\lib\urllib\request.pi line 223 urlopen return opener.openurl data timeout file c:\users\myusername\appdata\local\programs\python\python36\lib\urllib\request.pi line 526 open respons = self._openreq data file c:\users\myusername\appdata\local\programs\python\python36\lib\urllib\request.pi line 544 _open _open req file c:\users\myusername\appdata\local\programs\python\python36\lib\urllib\request.pi line 504 _call_chain result = func*arg file c:\users\myusername\appdata\local\programs\python\python36\lib\urllib\request.pi line 1361 https_open context=self._context check_hostname=self._check_hostnam file c:\users\myusername\appdata\local\programs\python\python36\lib\urllib\request.pi line 1320 do_open rais urlerrorerr urllib.error.urlerror found anoth post talk ad ssl context follow howev gener follow stacktrac matter much shake fist traceback recent call last file send_data.pi line 15 urlopenpost_it_alreadi context=ctx file c:\users\myusername\appdata\local\programs\python\python36\lib\urllib\request.pi line 223 urlopen return opener.openurl data timeout file c:\users\myusername\appdata\local\programs\python\python36\lib\urllib\request.pi line 526 open respons = self._openreq data file c:\users\myusername\appdata\local\programs\python\python36\lib\urllib\request.pi line 544 _open _open req file c:\users\myusername\appdata\local\programs\python\python36\lib\urllib\request.pi line 504 _call_chain result = func*arg file c:\users\myusername\appdata\local\programs\python\python36\lib\urllib\request.pi line 1361 https_open context=self._context check_hostname=self._check_hostnam file c:\users\myusername\appdata\local\programs\python\python36\lib\urllib\request.pi line 1318 do_open encode_chunked=req.has_head transfer-encod file c:\users\myusername\appdata\local\programs\python\python36\lib\http\client.pi line 1239 request self._send_requestmethod url bodi header encode_chunk file c:\users\myusername\appdata\local\programs\python\python36\lib\http\client.pi line 1285 _send_request self.endheadersbodi encode_chunked=encode_chunk file c:\users\myusername\appdata\local\programs\python\python36\lib\http\client.pi line 1234 endhead self._send_outputmessage_bodi encode_chunked=encode_chunk file c:\users\myusername\appdata\local\programs\python\python36\lib\http\client.pi line 1064 _send_output + b \r\n typeerror concat str byte loss complain concaten string byte object assum string type url data type payload headers? howev unsur next classic case someon take 2 separ sampl code expect work togeth fact peanut bubbl gum,0.16585365853658537,68,python python-3.x ssl urllib urlopen,post data use urllib without ssl certif valid,7,ssl|certificate|validate|signing|scripting|username|encode,0.3012100160121918
seem well establish etag md5sum file assembl run multi-part upload think case one recours download file perform checksum local result correct s3 copi must good local checksum wrong s3 copi bad download fail longer origin file record md5sum think luck great md5sum assembl file avail local comput expect etag file upload via multipart boto download file use method comput md5 checksum byte download make avail attribut object addit s3 send header respons repres server idea md5 checksum avail attribut object download file compar valu two attribut see match want find s3 think md5 without actual download file shown exampl,2013-06-01 12:23:10.023 UTC,186,16872679,refer post amazon s3 &amp checksum encod md5 sum base64 bash download tar file s3 bucket limit access [ mostli access permiss given download ] download check md5 check sum download file md5-check sum data present metadata s3 current s3 file browser manual note x-amz-meta-md5 content header valid valu comput md5 download file know programmat use boto captur md5 hash valu s3 file mention metadata pleas correct understand wrong look captur header data programmat,0.13978494623655913,26,amazon-s3 boto md5 python python-2.7,programmat md5 checksum amazon s3 file use boto,6,md5|checksum|encode|validate|hash|availability,0.29987871646881104
reset chang done metadata gone project settings.pi file ad,2020-04-17 11:21:59,234,61270418,librari suggest drf djangorestframework_simplejwt instal ad settings.pi creat two endpoint import view user creat without problem databa password hash go http://localhost:8000/api/token/ follow view post correct user password follow error [17/apr/2020 12:06:51] post /api/token/ http/1.1 500 122221 intern server error /api/token/ traceback recent call last file c:\users\tiago\desktop\letsgo\authenticationjwt\lib\site-packages\django\core\handlers\exception.pi line 34 inner respon = get_responserequest file c:\users\tiago\desktop\letsgo\authenticationjwt\lib\site-packages\django\core\handlers\base.pi line 115 _get_respon respon = self.process_exception_by_middlewar request file c:\users\tiago\desktop\letsgo\authenticationjwt\lib\site-packages\django\core\handlers\base.pi line 113 _get_respon respon = wrapped_callbackrequest *callback_arg **callback_kwarg file c:\users\tiago\desktop\letsgo\authenticationjwt\lib\site-packages\django\views\decorators\csrf.pi line 54 wrapped_view return view_func*arg **kwarg file c:\users\tiago\desktop\letsgo\authenticationjwt\lib\site-packages\django\views\generic\base.pi line 71 view return self.dispatchrequest *arg **kwarg file c:\users\tiago\desktop\letsgo\authenticationjwt\lib\site-packages\rest_framework\views.pi line 505 dispatch respon = self.handle_exceptionexc file c:\users\tiago\desktop\letsgo\authenticationjwt\lib\site-packages\rest_framework\views.pi line 465 handle_except self.raise_uncaught_exceptionexc file c:\users\tiago\desktop\letsgo\authenticationjwt\lib\site-packages\rest_framework\views.pi line 476 raise_uncaught_except rai exc file c:\users\tiago\desktop\letsgo\authenticationjwt\lib\site-packages\rest_framework\views.pi line 502 dispatch respon = handlerrequest *arg **kwarg file c:\users\tiago\desktop\letsgo\authenticationjwt\lib\site-packages\rest_framework_simplejwt\views.pi line 27 post serializer.is_validraise_exception=tru file c:\users\tiago\desktop\letsgo\authenticationjwt\lib\site-packages\rest_framework\serializers.pi line 234 is_valid self._validated_data = self.run_validationself.initial_data file c:\users\tiago\desktop\letsgo\authenticationjwt\lib\site-packages\rest_framework\serializers.pi line 436 run_valid valu = self.validatevalu file c:\users\tiago\desktop\letsgo\authenticationjwt\lib\site-packages\rest_framework_simplejwt\serializers.pi line 73 valid refresh = self.get_tokenself.u file c:\users\tiago\desktop\letsgo\authenticationjwt\lib\site-packages\rest_framework_simplejwt\serializers.pi line 68 get_token return refreshtoken.for_useru file c:\users\tiago\desktop\letsgo\authenticationjwt\lib\site-packages\rest_framework_simplejwt\tokens.pi line 161 for_u user_id = getattru api_settings.user_id_field attributeerror myuser object attribut id error clear myuser object attribut id instead primary_key see next thing want chang current myuser field edit go djangorestframework_simplejwt possibl read consid want chang myuser primary_key id gone place djangorestframework_simplejwt instal search user_id_field declar found venv\jwt\lib\site-packages\djangorestframework_simplejwt-4.4.0.dist-info\metadata simple_jwt chang restart venv runserv problem still happen,0.11538461538461539,27,python django django-rest-framework jwt django-rest-framework-simplejwt,drf jwt authent object attribut id,5,authentication|password|hash|csrf|validate,0.2966206967830658
assum want remov content origin file best possible.aft creat encrypt file overwrit origin file 0 byte delet note hdd ssd drive differ memori block overwrt file purpos wear level overwrit 0-byte use ssd ssd make sure trim enabl done depend os filesystem use thing ssd control determin re-us block memori obliter old content ssd cannot realli sure file content gone reason mention think better idea encrypt filesystem confidenti data rather encrypt individu file everyth written physic devic encrypt delet multipl file sever option give name file encrypt command line retriev script recurs retriev path file current work directori encrypt combin two path file test encrypt directori test find file directori encrypt,2018-01-02 03:16:44.37 UTC,179,48055209,creat data-protect program encrypt file comput use sha-256 far program capabl encrypt one specifi file hard-cod program time append .enc extens problem program creat new file encrypt instead save origin encrypt mypass.txt mypass.txt well mypass.enc need convert mypass.txt mypass.enc addit anyon idea encrypt file oppos one hard-cod extrem thankful.thank much anyon input pleas let know need addit inform,0.12290502793296089,22,cryptography encryption hash pycrypto python,encrypt multipl file python 2,7,crypt|encrypt|hash|protect|sha|confidential|scripting,0.2852296531200409
,2019-09-18 14:16:28,29,57994916,ii link file directli download excel file link request author user name password need python enter login data download file,0.1724137931034483,5,python python-3.x python-requests urllib wget,download file author pyhon,4,authorise|user name|password|login,0.28305327892303467
inde matter much put file especi discard import thing put place access webserv exampl static file and/or app code store directori put upload file exist django set call use default place store upload file path file store url path http client retriev upload file case need need realli care content csv file go store db re-us later valid care content store exampl store string later display site want make sure contain javascript,2016-01-29 08:43:19.08 UTC,128,35080194,build django app user upload csv file row csv file ad db valid data file discard django document use save file lot warn django site handl user upload file question file saved? guess matter want sure moment plan creat variabl call uploads_url set file upload file store,0.03125,4,csv django python security,store user upload file django,3,security|validate|scripting,0.27819401025772095
,2018-01-24 06:23:39.83 UTC,354,48416035,deploy web app ubuntu 16.04 vm implement standard django login book everyth work properli product environ os x howev attempt login receiv error exceptionvalu unsupport hash type run django version 1.11.6 requirements.txt use virtual environ run project traceback path follow traceback file /home/user_name/proj_folder/my_venv/lib/python3.5/site-packages/django/core/handlers/exception.pi inner 41 respons = get_responserequest file /home/user_name/proj_folder/my_venv/lib/python3.5/site-packages/django/core/handlers/base.pi _get_respons 187 respons = self.process_exception_by_middleware request file /home/user_name/proj_folder/my_venv/lib/python3.5/site-packages/django/core/handlers/base.pi _get_respons 185 respons = wrapped_callbackrequest *callback_arg **callback_kwarg file /home/user_name/proj_folder/my_venv/lib/python3.5/site-packages/django/contrib/auth/views.pi inner 54 return func*arg **kwarg file /home/user_name/proj_folder/my_venv/lib/python3.5/site-packages/django/contrib/auth/views.pi login 150 request file /home/user_name/proj_folder/my_venv/lib/python3.5/site-packages/django/views/generic/base.pi view 68 return self.dispatchrequest *arg **kwarg file /home/user_name/proj_folder/my_venv/lib/python3.5/site-packages/django/utils/decorators.pi _wrapper 67 return bound_func*arg **kwarg file /home/user_name/proj_folder/my_venv/lib/python3.5/site-packages/django/views/decorators/debug.pi sensitive_post_parameters_wrapp 76 return viewrequest *arg **kwarg file /home/user_name/proj_folder/my_venv/lib/python3.5/site-packages/django/utils/decorators.pi bound_func 63 return func self typeself*args2 **kwargs2 file /home/user_name/proj_folder/my_venv/lib/python3.5/site-packages/django/utils/decorators.pi _wrapper 67 return bound_func*arg **kwarg file /home/user_name/proj_folder/my_venv/lib/python3.5/site-packages/django/utils/decorators.pi _wrapped_view 149 respons = view_funcrequest *arg **kwarg file /home/user_name/proj_folder/my_venv/lib/python3.5/site-packages/django/utils/decorators.pi bound_func 63 return func self typeself*args2 **kwargs2 file /home/user_name/proj_folder/my_venv/lib/python3.5/site-packages/django/utils/decorators.pi _wrapper 67 return bound_func*arg **kwarg file /home/user_name/proj_folder/my_venv/lib/python3.5/site-packages/django/views/decorators/cache.pi _wrapped_view_func 57 respons = view_funcrequest *arg **kwarg file /home/user_name/proj_folder/my_venv/lib/python3.5/site-packages/django/utils/decorators.pi bound_func 63 return func self typeself*args2 **kwargs2 file /home/user_name/proj_folder/my_venv/lib/python3.5/site-packages/django/contrib/auth/views.pi dispatch 90 return superloginview self.dispatchrequest *arg **kwarg file /home/user_name/proj_folder/my_venv/lib/python3.5/site-packages/django/views/generic/base.pi dispatch 88 return handlerrequest *arg **kwarg file /home/user_name/proj_folder/my_venv/lib/python3.5/site-packages/django/views/generic/edit.pi post 182 form.is_valid file /home/user_name/proj_folder/my_venv/lib/python3.5/site-packages/django/forms/forms.pi is_valid 183 return self.is_bound self.error file /home/user_name/proj_folder/my_venv/lib/python3.5/site-packages/django/forms/forms.pi error 175 self.full_clean file /home/user_name/proj_folder/my_venv/lib/python3.5/site-packages/django/forms/forms.pi full_clean 385 self._clean_form file /home/user_name/proj_folder/my_venv/lib/python3.5/site-packages/django/forms/forms.pi _clean_form 412 cleaned_data = self.clean file /home/user_name/proj_folder/my_venv/lib/python3.5/site-packages/django/contrib/auth/forms.pi clean 187 self.user_cach = authenticateself.request username=usernam password=password file /home/user_name/proj_folder/my_venv/lib/python3.5/site-packages/django/contrib/auth/ init .py authent 70 user = _authenticate_with_backendbackend backend_path request credenti file /home/user_name/proj_folder/my_venv/lib/python3.5/site-packages/django/contrib/auth/ init .py _authenticate_with_backend 115 return backend.authenticate*arg **credenti file /home/user_name/proj_folder/my_venv/lib/python3.5/site-packages/django/contrib/auth/backends.pi authent 24 user.check_passwordpassword self.user_can_authenticateus file /home/user_name/proj_folder/my_venv/lib/python3.5/site-packages/django/contrib/auth/base_user.pi check_password 118 return check_passwordraw_password self.password setter file /home/user_name/proj_folder/my_venv/lib/python3.5/site-packages/django/contrib/auth/hashers.pi check_password 52 is_correct = hasher.verifypassword encod file /home/user_name/proj_folder/my_venv/lib/python3.5/site-packages/django/contrib/auth/hashers.pi verifi 265 encoded_2 = self.encodepassword salt intiter file /home/user_name/proj_folder/my_venv/lib/python3.5/site-packages/django/contrib/auth/hashers.pi encod 258 hash = pbkdf2password salt iter digest=self.digest file /home/user_name/proj_folder/my_venv/lib/python3.5/site-packages/django/utils/crypto.pi pbkdf2 140 digest.nam password salt iter dklen except type valueerror /login/ except valu unsupport hash type traceback entir within venv folder final error shown line 133-146 /home/user_name/proj_folder/my_env/lib/python3.5/site-packages/django/utils/crypto.pi pbkdf2 final except thrown local var seen similar question relat solari 10 problem ssl installation/vers openssl instal machin although differ version abl success run applic remov login requir better understand go version error develop product environ caus python openssl,0.15819209039548024,56,django hashlib python ubuntu-16.04,django ubuntu 16.04 unsupport hash type,13,hash|login|validate|authentication|username|password|credential|encode|salt|pbkdf2|crypt|ssl|openssl,0.27264443039894104
decod standard input input valid json,2016-06-09 23:37:10.44 UTC,88,37737831,run follow code call caa_fiel_write.pi output splunk result json file follow error file /opt/sdg/splunk/etc/apps/sdg/bin/caa_file_write.pi line 7 caa_config = json.loadssys.stdin.read file /opt/sdg/splunk/lib/python2.7/json/__init__.pi line 339 load return _default_decoder.decod file /opt/sdg/splunk/lib/python2.7/json/decoder.pi line 364 decod obj end = self.raw_decod idx=_w 0.end file /opt/sdg/splunk/lib/python2.7/json/decoder.pi line 382 raw_decod rais valueerrorno json object decod valueerror json object decod line 339 __init__.pi line 364 382 decoder.pi sure call decod first place encod __init__.pi decoder.pi standard splunk python file avail distribut error fix,0.18181818181818182,16,python python-2.7 splunk,splunk custom alert python issu,4,decode|encode|availability|validate,0.26627635955810547
give whole process larg explan mention point encrypt file first second script want read content file must link server applic receiv decrypt key send data server whether file read file read earlier server send decrypt key receiv key script decrypt file read,2018-10-20 17:32:00.39 UTC,132,52908310,tri creat script script #1 write file read global anoth script script #2 read file never read world exampl situat creat csv file script #1 email csv file 10 peopl differ comput 10 try run file script #2 expect behaviour first person world run script #2 file get messag say first person read file actual see content 2nd -10th person try read file messag say someon alreadi read access file accomplish this? someth seriou realli worri secur process want work,0.12121212121212122,16,csv encryption file python,ensur global file read python script,4,encrypt|crypt|scripting|security,0.2610962390899658
got sort perhap raise_exceptions=tru set fals resolv issu,2016-12-05 10:52:58.857 UTC,213,40972550,"tri valid usernam password user flask app use ldap3 normal ldap instal python 3.5 user enter usernam password login form tri authent user usernam / password allow access index page authent authent return true fals redirect next page base outcome.th pleas help code this.when type host follow error r_web c:\users\dasa17\r_web\rosterweb\rosterweb>python roster.pi traceback recent call last file roster.pi line 10 = serverappauth.corp.domain.com port=636 get_info=al nameerror name appauth defin r_web c:\users\dasa17\r_web\rosterweb\rosterweb>python roster.pi traceback recent call last file roster.pi line 10 = servercorp.domain.com port=636 get_info=al nameerror name corp defin made modif abl run give dummi usernam password howev get differ error now.>>> c = connections,user= dasa17 ,password= ,check_names=tru lazy=false,raise_exceptions=fals c.open traceback recent call last file line 1 c.open file c:\python35\lib\site-packages\ldap3\strategy\sync.pi line 57 open self.connection.refresh_server_info file c:\python35\lib\site-packages\ldap3\core\connection.pi line 1017 refresh_server_info self.server.get_info_from_serverself file c:\python35\lib\site-packages\ldap3\core\server.pi line 382 get_info_from_serv self._get_dsa_infoconnect file c:\python35\lib\site-packages\ldap3\core\server.pi line 308 _get_dsa_info get_operational_attributes=tru file c:\python35\lib\site-packages\ldap3\core\connection.pi line 571 search respons = self.post_send_searchself.send searchrequest request control file c:\python35\lib\site-packages\ldap3\strategy\sync.pi line 140 post_send_search respons result = self.get_responsemessage_id file c:\python35\lib\site-packages\ldap3\strategy\base.pi line 298 get_respons respons = self._get_responsemessage_id file c:\python35\lib\site-packages\ldap3\strategy\sync.pi line 158 _get_respons respons = self.receiv file c:\python35\lib\site-packages\ldap3\strategy\sync.pi line 92 receiv rais communication_exception_factoryldapsocketreceiveerror exc self.connection.last_error ldap3.core.exceptions.ldapsocketreceiveerror error receiv data [winerror 10054] exist connect forcibl close remot host",0.14553990610328638,31,compiler-errors flask python-3.x,ldap3 bind syntax error flask applic,7,ldap|validate|username|password|login|authentication|dsa,0.2416737973690033
like trial subscript cancel sign actual account one tier free like requir provid payment inform anyway either repeatedli violat term service/us agreement,2018-10-02 03:12:18.52 UTC,123,52601521,python app use sendgird account heroku send email user forgot password login link.problem sendgrid account 1-2 month use disabl must chang new account full log error traceback recent call last file user_profile/services/profile.pi line 595 send_mail_with_perm msg.sendfail_silently=fail_sil file /app/.heroku/python/lib/python2.7/site-packages/django/core/mail/message.pi line 292 send return self.get_connectionfail_silently.send_messages[self] file /app/.heroku/python/lib/python2.7/site-packages/email_log/backends.pi line 27 send_messag num_sent += message.send file /app/.heroku/python/lib/python2.7/site-packages/django/core/mail/message.pi line 292 send return self.get_connectionfail_silently.send_messages[self] file /app/.heroku/python/lib/python2.7/site-packages/django/core/mail/backends/smtp.pi line 100 send_messag new_conn_cr = self.open file /app/.heroku/python/lib/python2.7/site-packages/django/core/mail/backends/smtp.pi line 67 open self.connection.loginself.usernam self.password file /app/.heroku/python/lib/python2.7/smtplib.pi line 623 login rais smtpauthenticationerrorcod resp smtpauthenticationerror 535 authent fail account disabl anyon problem,0.12195121951219512,15,django heroku python sendgrid,smtpauthenticationerror 535 authent fail account disabl python app,8,authentication|forge|password|login|username|scripting|signing|violate,0.23920634388923645
perfect usecas request built-in authent 1 read file line line http://docs.python.org/tutorial/inputoutput.html 2 split line string http://docs.python.org/library/string.html 3 post inform http://docs.python.org/library/urllib.html googl help figur step assum charact usernam password,2012-01-30 02:40:58.317 UTC,58,9058764,text file usernam password text file format want grab first line split username1 password1 post want repeat move onto username2:password2 done,0.20689655172413793,12,file python,grab username:password text file post login form,4,username|password|login|authentication,0.2296019196510315
simpli open read line compar impli advanc procedur simpl statement work,2012-01-11 14:23:56.717 UTC,45,8820892,sake practic make md5 decod encod someth hash ad databas go encrypt save text hash file one encryption/decrypt line look line equal x thefil,0.2222222222222222,10,file hash md5 python,python find line == x file,6,hash|md5|decode|encode|encrypt|crypt,0.22813405096530914
accord latest doc http://docs.aws.amazon.com/amazons3/latest/api/sigv4-query-string-auth.html presign url valid maximum seven day sign key signatur calcul valid seven day sinc signatur valid seven day sign url valid seven day perman valid url make file public link expir allow limit access privat file without expos authent key want make file alway avail either make file public provid permiss s3 user,2013-07-24 10:35:06.76 UTC,81,17831535,aws s3 gener file download url file without expiri gener url file without expiri,0.14814814814814814,12,amazon-ec2 amazon-s3 amazon-web-services boto python,gener file link without expiri,5,signing|validate|signature|authentication|availability,0.20562617480754852
distutil command configur file put option valu section name command specifi option command write distribut file,2017-03-12 06:30:50.223 UTC,62,42744510,distutil command upload distribut pypi specifi first sign distribut upload signatur option tell upload sign upload file use gpg gnu privaci guard […] specifi key sign use option specifi particular distribut everi upload sign particular key,0.14516129032258066,9,digital-signature python software-distribution,specifi alway gnupg sign upload distribut pypi,4,signing|signature|gnupg|privacy,0.19952858984470367
